Workbook

Sheet Overview
B2: ISO/IEC 27001:2022 — Annex A Gap Assessment
B3: GridFlex Technologies
B5: Organization | C5: GridFlex Technologies (fictional) — SaaS company providing a customizable AI app builder for CRM, Help Desk, Ticketing, and Operations.
B6: Size | C6: ~120 employees
B7: Infrastructure | C7: AWS-hosted (multi-AZ), web application + database tier in VPC, GitHub for source control
B8: Data Handled | C8: Customer business data (contacts, tickets, operational records) — confidential but not regulated health/financial data
B9: Assessment Scope | C9: Full Annex A (2022 revision) — 93 controls across 4 themes: Organizational (37), People (8), Physical (14), Technological (34)
B10: Methodology | C10: Each control assessed against current practice; status rated as Implemented / Partially Implemented / Not Implemented. Gaps identified, risk-rated (High/Medium/Low) based on likelihood and business impact, with remediation recommendations and a phased roadmap.
B11: Purpose | C11: Self-directed learning exercise to build practical GRC / ISO 27001 assessment experience ahead of IT Security / GRC role interviews.
B13: Status Legend
B14: Implemented
B15: Partially Implemented
B16: Not Implemented
B18: Risk Rating Legend
B19: High
B20: Medium
B21: Low
B24: See 'Gap Assessment' sheet for the full control register, 'Dashboard' for summary stats, and 'Remediation Roadmap' for the phased action plan.

Sheet Gap Assessment
A1: Control ID | B1: Control Name | C1: Theme | D1: Status | E1: Current State / Evidence | F1: Gap Description | G1: Risk Rating | H1: Recommended Remediation | I1: Owner (Role) | J1: Target Timeline
A2: A.5.1 | B2: Policies for information security | C2: Organizational | D2: Partially Implemented | E2: Informal IT usage guidelines doc shared during onboarding, not formally approved or periodically reviewed by management. | F2: No formal Information Security Policy approved by leadership; no defined review cycle. | G2: Medium | H2: Draft and obtain management sign-off on a formal Information Security Policy; schedule annual review. | I2: IT Manager / Mgmt | J2: 30-90 days
A3: A.5.2 | B3: Information security roles and responsibilities | C3: Organizational | D3: Not Implemented | E3: IT team handles security tasks informally as part of general IT duties; no dedicated security role. | F3: No documented RACI for security responsibilities (risk decisions, incident response, policy approval). | G3: High | H3: Define and document security roles (e.g., IT Manager as interim Security Lead) with clear responsibilities; budget for future dedicated hire. | I3: IT Manager / Mgmt | J3: 0-30 days
A4: A.5.3 | B4: Segregation of duties | C4: Organizational | D4: Partially Implemented | E4: Dev and ops teams are separate, but a few senior engineers have both deployment and production database access. | F4: No formal SoD matrix; conflicting access combinations not reviewed. | G4: Medium | H4: Map SoD conflicts (dev vs prod access), restrict where possible, document compensating controls where not. | I4: IT Manager / Mgmt | J4: 30-90 days
A5: A.5.4 | B5: Management responsibilities | C5: Organizational | D5: Partially Implemented | E5: Managers verbally remind teams about security during meetings but it's not formalized. | F5: No written expectation that managers enforce security policy compliance within their teams. | G5: Low | H5: Add security responsibilities to manager job descriptions/performance reviews. | I5: IT Manager / Mgmt | J5: 90-180 days
A6: A.5.5 | B6: Contact with authorities | C6: Organizational | D6: Not Implemented | E6: No documented process for contacting law enforcement, data protection authorities, or CERTs during an incident. | F6: No contact list or escalation process exists. | G6: Medium | H6: Create contact list (cybercrime cell, relevant data protection authority) and include in IR plan. | I6: IT Manager / Mgmt | J6: 30-90 days
A7: A.5.6 | B7: Contact with special interest groups | C7: Organizational | D7: Not Implemented | E7: No memberships or subscriptions to threat intel communities, ISACs, or security forums. | F7: No external threat awareness channel. | G7: Low | H7: Subscribe to relevant threat intel feeds (e.g., AWS security bulletins, CERT-In advisories). | I7: IT Manager / Mgmt | J7: 90-180 days
A8: A.5.7 | B8: Threat intelligence | C8: Organizational | D8: Not Implemented | E8: No formal threat intelligence gathering; team reacts to incidents as they occur. | F8: No proactive threat monitoring process. | G8: Medium | H8: Subscribe to AWS Security Hub findings and relevant CVE feeds for tech stack in use. | I8: IT Manager / Mgmt | J8: 30-90 days
A9: A.5.8 | B9: Information security in project management | C9: Organizational | D9: Not Implemented | E9: New feature development doesn't include a security review step. | F9: Security not embedded in SDLC/project lifecycle. | G9: High | H9: Add a security checklist/review gate to project planning templates for new features. | I9: IT Manager / Mgmt | J9: 0-30 days
A10: A.5.9 | B10: Inventory of information and other associated assets | C10: Organizational | D10: Partially Implemented | E10: AWS resources tracked via console/tags, but no centralized asset register including data types, owners, criticality. | F10: No formal asset inventory covering hardware, software, data, and cloud resources with classification. | G10: High | H10: Build centralized asset register (spreadsheet or CMDB) covering all assets with owner and classification. | I10: IT Manager / Mgmt | J10: 0-30 days
A11: A.5.10 | B11: Acceptable use of information and other associated assets | C11: Organizational | D11: Implemented | E11: Acceptable Use Policy exists, signed during onboarding, covers company devices and data handling. | F11: Not reviewed/updated since initial creation (2 years ago). | G11: Low | H11: Schedule annual policy review and re-acknowledgment by staff. | I11: IT Manager / Mgmt | J11: 90-180 days
A12: A.5.11 | B12: Return of assets | C12: Organizational | D12: Partially Implemented | E12: Offboarding checklist includes laptop/badge return, but not consistently tracked for all items (access cards, USB drives). | F12: No formal sign-off form confirming all assets returned before final clearance. | G12: Low | H12: Create asset return checklist as part of formal offboarding sign-off, signed by HR and IT. | I12: IT Manager / Mgmt | J12: 90-180 days
... A94: A.8.34 | B94: Protection of information systems during audit testing | C94: Technological | D94: Not Implemented | E94: No audits/pen tests conducted yet, so no controls defined for protecting systems during such activities. | F94: No guidelines for safely conducting audits/pen tests without disrupting production. | G94: Low | H94: When planning first pen test/audit, define scope, timing, and safeguards (test in staging, rate-limit scans) in advance. | I94: IT / Engineering | J94: 90-180 days

Sheet Dashboard
B2: ISO 27001 Annex A — Gap Assessment Dashboard
B3: GridFlex Technologies
B5: By Status
B6: Status | C6: Count | D6: % of Total
B7: Implemented | C7: =COUNTIF('Gap Assessment'!D2:D94,B7) -> 11 | D7: =C7/93 -> 0.11827957
B8: Partially Implemented | C8: =COUNTIF('Gap Assessment'!D2:D94,B8) -> 44 | D8: =C8/93 -> 0.47311828
B9: Not Implemented | C9: =COUNTIF('Gap Assessment'!D2:D94,B9) -> 38 | D9: =C9/93 -> 0.40860215
B10: Total | C10: =SUM(C7:C9) -> 93
B13: By Risk Rating
B14: Risk | C14: Count | D14: % of Total
B15: High | C15: =COUNTIF('Gap Assessment'!G2:G94,B15) -> 28 | D15: =C15/93 -> 0.30107527
B16: Medium | C16: =COUNTIF('Gap Assessment'!G2:G94,B16) -> 40 | D16: =C16/93 -> 0.43010753
B17: Low | C17: =COUNTIF('Gap Assessment'!G2:G94,B17) -> 25 | D17: =C17/93 -> 0.2688172
B18: Total | C18: =SUM(C15:C17) -> 93
B21: By Theme — Implementation Status
B22: Theme | C22: Total | D22: Implemented | E22: Partial | F22: Not Impl. | G22: High Risk Gaps
B23: Organizational | C23: =COUNTIF('Gap Assessment'!C2:C94,B23) -> 37 | D23: =COUNTIFS('Gap Assessment'!C2:C94,B23,'Gap Assessment'!D2:D94,"Implemented") -> 1 | E23: =COUNTIFS('Gap Assessment'!C2:C94,B23,'Gap Assessment'!D2:D94,"Partially Implemented") -> 19 | F23: =COUNTIFS('Gap Assessment'!C2:C94,B23,'Gap Assessment'!D2:D94,"Not Implemented") -> 17 | G23: =COUNTIFS('Gap Assessment'!C2:C94,B23,'Gap Assessment'!G2:G94,"High") -> 13
B24: People | C24: =COUNTIF('Gap Assessment'!C2:C94,B24) -> 8 | D24: =COUNTIFS('Gap Assessment'!C2:C94,B24,'Gap Assessment'!D2:D94,"Implemented") -> 3 | E24: =COUNTIFS('Gap Assessment'!C2:C94,B24,'Gap Assessment'!D2:D94,"Partially Implemented") -> 3 | F24: =COUNTIFS('Gap Assessment'!C2:C94,B24,'Gap Assessment'!D2:D94,"Not Implemented") -> 2 | G24: =COUNTIFS('Gap Assessment'!C2:C94,B24,'Gap Assessment'!G2:G94,"High") -> 2
B25: Physical | C25: =COUNTIF('Gap Assessment'!C2:C94,B25) -> 14 | D25: =COUNTIFS('Gap Assessment'!C2:C94,B25,'Gap Assessment'!D2:D94,"Implemented") -> 3 | E25: =COUNTIFS('Gap Assessment'!C2:C94,B25,'Gap Assessment'!D2:D94,"Partially Implemented") -> 7 | F25: =COUNTIFS('Gap Assessment'!C2:C94,B25,'Gap Assessment'!D2:D94,"Not Implemented") -> 4 | G25: =COUNTIFS('Gap Assessment'!C2:C94,B25,'Gap Assessment'!G2:G94,"High") -> 1
B26: Technological | C26: =COUNTIF('Gap Assessment'!C2:C94,B26) -> 34 | D26: =COUNTIFS('Gap Assessment'!C2:C94,B26,'Gap Assessment'!D2:D94,"Implemented") -> 4 | E26: =COUNTIFS('Gap Assessment'!C2:C94,B26,'Gap Assessment'!D2:D94,"Partially Implemented") -> 15 | F26: =COUNTIFS('Gap Assessment'!C2:C94,B26,'Gap Assessment'!D2:D94,"Not Implemented") -> 15 | G26: =COUNTIFS('Gap Assessment'!C2:C94,B26,'Gap Assessment'!G2:G94,"High") -> 12
B27: Total | C27: =SUM(C23:C26) -> 93 | D27: =SUM(D23:D26) -> 11 | E27: =SUM(E23:E26) -> 44 | F27: =SUM(F23:F26) -> 38 | G27: =SUM(G23:G26) -> 28
B30: Overall Maturity Score
B31: Score = (Implemented x1 + Partial x0.5) / Total controls
B32: =(C7*1 + C8*0.5 + C9*0) / 93 -> 0.35483871

Sheet Remediation Roadmap
A2: Remediation Roadmap — Phased Plan
A3: Priority sequencing based on Risk Rating: High = 0-30 days, Medium = 30-90 days, Low = 90-180 days
A5: Phase 1: 0-30 Days (Critical / High Risk)
A6: Control ID | B6: Control Name | C6: Gap Description | D6: Remediation Action | E6: Owner
A7: A.5.2 | B7: Information security roles and responsibilities | C7: No documented RACI for security responsibilities (risk decisions, incident response, policy approval). | D7: Define and document security roles (e.g., IT Manager as interim Security Lead) with clear responsibilities; budget for future dedicated hire. | E7: IT Manager / Mgmt
A8: A.5.8 | B8: Information security in project management | C8: Security not embedded in SDLC/project lifecycle. | D8: Add a security checklist/review gate to project planning templates for new features. | E8: IT Manager / Mgmt
A9: A.5.9 | B9: Inventory of information and other associated assets | C9: No formal asset inventory covering hardware, software, data, and cloud resources with classification. | D9: Build centralized asset register (spreadsheet or CMDB) covering all assets with owner and classification. | E9: IT Manager / Mgmt
A10: A.5.12 | B10: Classification of information | C10: No data classification scheme (Public/Internal/Confidential/Restricted). | D10: Define a simple 3-4 tier classification scheme and apply it to key data repositories. | E10: IT Manager / Mgmt
A11: A.5.14 | B11: Information transfer | C11: No policy governing secure transfer methods for sensitive data (e.g., mandatory encryption, approved channels). | D11: Define approved secure transfer methods (encrypted email, secure file share); train staff on usage. | E11: IT Manager / Mgmt
A12: A.5.15 | B12: Access control | C12: No formal Access Control Policy defining how access is granted, reviewed, revoked. | D12: Document Access Control Policy; implement quarterly access reviews for critical systems. | E12: IT Manager / Mgmt
A13: A.5.18 | B13: Access rights | C13: No formal joiner-mover-leaver (JML) process with SLA for access changes. | D13: Implement JML process - access provisioning/de-provisioning tied to HR triggers, with 24-hour SLA for revocation. | E13: IT Manager / Mgmt
A14: A.5.19 | B14: Information security in supplier relationships | C14: No supplier security risk assessment process. | D14: Create a vendor security questionnaire; assess critical suppliers before/after contracting. | E14: IT Manager / Mgmt
A15: A.5.23 | B15: Information security for use of cloud services | C15: No documented cloud usage policy; shared responsibility model not formally documented. | D15: Document cloud security policy covering AWS shared responsibility model, configuration standards, approval for new cloud services. | E15: IT Manager / Mgmt
A16: A.5.24 | B16: Information security incident management planning and preparation | C16: No documented Incident Response Plan with roles, escalation paths, communication templates. | D16: Create formal IR plan covering detection, triage, containment, communication, and recovery roles. | E16: IT Manager / Mgmt
A17: A.5.26 | B17: Response to information security incidents | C17: No standardized response playbooks for common incident types (compromised credentials, malware). | D17: Build incident-specific playbooks (phishing, ransomware, data leak) mapped to IR plan. | E17: IT Manager / Mgmt
... A34: A.8.33 | B34: Test information | C34: Overlaps with A.8.11 - sensitive test data not protected. | D34: Use anonymized/synthetic data for testing; if production data must be used, apply masking first. | E34: IT / Engineering
A37: Phase 2: 30-90 Days (Medium Risk)
A38: Control ID | B38: Control Name | C38: Gap Description | D38: Remediation Action | E38: Owner
A39: A.5.1 | B39: Policies for information security | C39: No formal Information Security Policy approved by leadership; no defined review cycle. | D39: Draft and obtain management sign-off on a formal Information Security Policy; schedule annual review. | E39: IT Manager / Mgmt
A40: A.5.3 | B40: Segregation of duties | C40: No formal SoD matrix; conflicting access combinations not reviewed. | D40: Map SoD conflicts (dev vs prod access), restrict where possible, document compensating controls where not. | E40: IT Manager / Mgmt
A41: A.5.5 | B41: Contact with authorities | C41: No contact list or escalation process exists. | D41: Create contact list (cybercrime cell, relevant data protection authority) and include in IR plan. | E41: IT Manager / Mgmt
A42: A.5.7 | B42: Threat intelligence | C42: No proactive threat monitoring process. | D42: Subscribe to AWS Security Hub findings and relevant CVE feeds for tech stack in use. | E42: IT Manager / Mgmt
A43: A.5.16 | B43: Identity management | C43: Shared accounts make it hard to trace individual actions; no formal identity lifecycle process. | D43: Reduce shared accounts where possible; for unavoidable ones, implement logging/checkout process. | E43: IT Manager / Mgmt
A44: A.5.17 | B44: Authentication information | C44: No documented standard covering password rotation, MFA enforcement scope, secret storage. | D44: Document authentication standard; enforce MFA for all admin/privileged accounts. | E44: IT Manager / Mgmt
A45: A.5.20 | B45: Addressing information security within supplier agreements | C45: Contracts don't specify security requirements, breach notification timelines, audit rights. | D45: Add standard security clauses to vendor contract templates (data protection, breach notification SLA, right to audit). | E45: IT Manager / Mgmt
A46: A.5.21 | B46: Managing information security in the ICT supply chain | C46: ICT supply chain risk unaddressed. | D46: Include supply-chain security questions in vendor assessments (A.5.19). | E46: IT Manager / Mgmt
A47: A.5.22 | B47: Monitoring, review and change management of supplier services | C47: No periodic supplier security review. | D47: Annual supplier security review for critical vendors; track changes to their services/security posture. | E47: IT Manager / Mgmt
A48: A.5.25 | B48: Assessment and decision on information security events | C48: No event classification/triage criteria. | D48: Define event severity levels and escalation criteria as part of IR plan. | E48: IT Manager / Mgmt
A49: A.5.27 | B49: Learning from information security incidents | C49: No formal post-incident review (PIR) process. | D49: Conduct PIR after each incident; maintain lessons-learned log feeding into policy/control updates. | E49: IT Manager / Mgmt
... A78: A.8.32 | B78: Change management | C78: No documented change management process for infrastructure/config changes (especially production AWS changes). | D78: Extend change management process to cover infrastructure changes - require review/approval before production changes. | E78: IT / Engineering
A81: Phase 3: 90-180 Days (Low Risk / Continuous Improvement)
A82: Control ID | B82: Control Name | C82: Gap Description | D82: Remediation Action | E82: Owner
A83: A.5.4 | B83: Management responsibilities | C83: No written expectation that managers enforce security policy compliance within their teams. | D83: Add security responsibilities to manager job descriptions/performance reviews. | E83: IT Manager / Mgmt
A84: A.5.6 | B84: Contact with special interest groups | C84: No external threat awareness channel. | D84: Subscribe to relevant threat intel feeds (e.g., AWS security bulletins, CERT-In advisories). | E84: IT Manager / Mgmt
A85: A.5.10 | B85: Acceptable use of information and other associated assets | C85: Not reviewed/updated since initial creation (2 years ago). | D85: Schedule annual policy review and re-acknowledgment by staff. | E85: IT Manager / Mgmt
A86: A.5.11 | B86: Return of assets | C86: No formal sign-off form confirming all assets returned before final clearance. | D86: Create asset return checklist as part of formal offboarding sign-off, signed by HR and IT. | E86: IT Manager / Mgmt
A87: A.5.13 | B87: Labelling of information | C87: Without classification (A.5.12), labelling can't be applied either. | D87: Once classification scheme exists, apply labels via document templates/metadata tags (e.g., 'Confidential' footer). | E87: IT Manager / Mgmt
A88: A.5.32 | B88: Intellectual property rights | C88: No periodic audit of software license compliance (open-source usage, paid tool licenses). | D88: Conduct annual software license/IP compliance review, including OSS license checks. | E88: IT Manager / Mgmt
A89: A.6.2 | B89: Terms and conditions of employment | C89: Not reviewed since company's early days. | D89: Review contract templates to ensure they reflect current security policies. | E89: HR / IT Manager
A90: A.6.4 | B90: Disciplinary process | C90: None significant. | D90: Ensure security violations are explicitly referenced in disciplinary policy documentation. | E90: HR / IT Manager
...
